<?xml version="1.0"?>
<!-- Copyright (c) 2016 The UUV Simulator Authors.
     All rights reserved.

     Licensed under the Apache License, Version 2.0 (the "License");
     you may not use this file except in compliance with the License.
     You may obtain a copy of the License at

       http://www.apache.org/licenses/LICENSE-2.0

     Unless required by applicable law or agreed to in writing, software
     distributed under the License is distributed on an "AS IS" BASIS,
     WITHOUT WARRANTIES OR CONDITIONS OF ANY KIND, either express or implied.
     See the License for the specific language governing permissions and
     limitations under the License.
-->
<robot xmlns:xacro="http://www.ros.org/wiki/xacro">
  <xacro:property name="prop_mesh_file" value="file://$(find desistek_saga_description)/mesh/propeller.dae"/>

  <!-- Thruster macro with integration of joint and link-->
  <xacro:macro name="thruster_macro" params="robot_namespace thruster_id *origin">
    <link name="${robot_namespace}/thruster_${thruster_id}">
      <visual>
        <geometry>
          <mesh filename="${prop_mesh_file}" scale="1 1 1" />
        </geometry>
      </visual>

      <inertial>
        <mass value="0.001" />
        <origin xyz="0 0 0" rpy="0 0 0"/>
        <inertia ixx="0.000000017" ixy="0.0" ixz="0.0"
               iyy="0.000000017" iyz="0.0"
               izz="0.000000017" />
      </inertial>
    </link>

    <joint name="${robot_namespace}/thruster_${thruster_id}_joint" type="continuous">
      <xacro:insert_block name="origin" />
      <axis xyz="1 0 0" />
      <parent link="${robot_namespace}/base_link" />
      <child link="${robot_namespace}/thruster_${thruster_id}" />
    </joint>

    <gazebo>
      <plugin name="${robot_namespace}_${thruster_id}_thruster_model" filename="libthruster_ros_plugin.so">
        <linkName>${robot_namespace}/thruster_${thruster_id}</linkName>
        <jointName>${robot_namespace}/thruster_${thruster_id}_joint</jointName>
        <thrusterID>${thruster_id}</thrusterID>
        <gain>5</gain>
        <dynamics>
          <type>FirstOrder</type>
          <timeConstant>0.2</timeConstant>
        </dynamics>
        <conversion>
          <type>Basic</type>
          <rotorConstant>0.00001</rotorConstant>
        </conversion>
      </plugin>
    </gazebo>

    <gazebo reference="${robot_namespace}/thruster_${thruster_id}">
      <selfCollide>false</selfCollide>
    </gazebo>
  </xacro:macro>

</robot>
